Workbook

Sheet Test 1,2
H2: Test 1 - Conditional (duplication) formatting done - no significant observations | U2: Test 2
B4: S. No. | C4: Transaction Id | D4: Invoice Number | E4: Unique Contract No. | F4: Customer Id | G4: Posting cum auto-invoice Generation Date | H4: Posted Timestamp | I4: Service Period | J4: Recorded Revenue | K4: Currency | L4: Tax Amount | M4: Creator Id | N4: Approver Id | O4: Board Approval | P4: Board Approval No | Q4: Creator Limits Reperformed | R4: Approval Limits Reperformed | S4: Current Creator | T4: Current Approver | U4: Limits test | V4: Board approval test | W4: Year of Revenue | X4: Month of revenue | Y4: Whether RP?
B5: 1 | C5: 2021O81900 | D5: 20211 | E5: CC272485 | F5: C205 | G5: 43922 | H5: 0.43784988 | I5: Apr | J5: 483830 | K5: INR | L5: 87089.4 | M5: E115 | N5: E118 | O5: NA | P5: NA | Q5: =IF(J5<200000,"SE",IF(J5<500000,"AM",IF(J5<1000000,"DM",IF(J5<4500000,"SM",IF(J5>=4500000,"CM"))))) -> AM | R5: =IF(Q5="SE","AM",IF(Q5="AM","DM",IF(Q5="DM","SM",IF(Q5="SM","CM",IF(Q5="CM","CFO"))))) -> DM | S5: =VLOOKUP(M5,'Data - Employee Rights Master'!$C$3:$D$32,2,0) -> AM | T5: =VLOOKUP(N5,'Data - Employee Rights Master'!$C$3:$D$32,2,0) -> DM | U5: =IF(AND(S5=Q5,T5=R5),"PASS","DEVIATION") -> PASS | V5: =IF(J5>5000000,IF(AND(O5="Approved",P5<>"NA"),"PASS","FLAG"),"NA") -> NA | W5: =LEFT(C5,4) -> 2021 | X5: =VLOOKUP(MONTH(G5),Key!$F$3:$G$14,2,0) -> Apr | Y5: =IFERROR(IF(MATCH(F5,'Test 6'!C$5:C$9,0)>0,"RP"),"NON-RP") -> NON-RP
B6: 2 | C6: 2021M11625 | D6: 20212 | E6: CC889281 | F6: C219 | G6: 43924 | H6: 0.4213918 | I6: Apr | J6: 462100 | K6: INR | L6: 83178 | M6: E111 | N6: E117 | O6: NA | P6: NA | Q6: =IF(J6<200000,"SE",IF(J6<500000,"AM",IF(J6<1000000,"DM",IF(J6<4500000,"SM",IF(J6>=4500000,"CM"))))) -> AM | R6: =IF(Q6="SE","AM",IF(Q6="AM","DM",IF(Q6="DM","SM",IF(Q6="SM","CM",IF(Q6="CM","CFO"))))) -> DM | S6: =VLOOKUP(M6,'Data - Employee Rights Master'!$C$3:$D$32,2,0) -> AM | T6: =VLOOKUP(N6,'Data - Employee Rights Master'!$C$3:$D$32,2,0) -> DM | U6: =IF(AND(S6=Q6,T6=R6),"PASS","DEVIATION") -> PASS | V6: =IF(J6>5000000,IF(AND(O6="Approved",P6<>"NA"),"PASS","FLAG"),"NA") -> NA | W6: =LEFT(C6,4) -> 2021 | X6: =VLOOKUP(MONTH(G6),Key!$F$3:$G$14,2,0) -> Apr | Y6: =IFERROR(IF(MATCH(F6,'Test 6'!C$5:C$9,0)>0,"RP"),"NON-RP") -> NON-RP
B7: 3 | C7: 2021S01216 | D7: 20213 | E7: CC738783 | F7: C224 | G7: 43924 | H7: 0.49380763 | I7: Apr | J7: 372600 | K7: INR | L7: 67068 | M7: E116 | N7: E117 | O7: NA | P7: NA | Q7: =IF(J7<200000,"SE",IF(J7<500000,"AM",IF(J7<1000000,"DM",IF(J7<4500000,"SM",IF(J7>=4500000,"CM"))))) -> AM | R7: =IF(Q7="SE","AM",IF(Q7="AM","DM",IF(Q7="DM","SM",IF(Q7="SM","CM",IF(Q7="CM","CFO"))))) -> DM | S7: =VLOOKUP(M7,'Data - Employee Rights Master'!$C$3:$D$32,2,0) -> AM | T7: =VLOOKUP(N7,'Data - Employee Rights Master'!$C$3:$D$32,2,0) -> DM | U7: =IF(AND(S7=Q7,T7=R7),"PASS","DEVIATION") -> PASS | V7: =IF(J7>5000000,IF(AND(O7="Approved",P7<>"NA"),"PASS","FLAG"),"NA") -> NA | W7: =LEFT(C7,4) -> 2021 | X7: =VLOOKUP(MONTH(G7),Key!$F$3:$G$14,2,0) -> Apr | Y7: =IFERROR(IF(MATCH(F7,'Test 6'!C$5:C$9,0)>0,"RP"),"NON-RP") -> NON-RP
B8: 4 | C8: 2021V81178 | D8: 20214 | E8: CC797872 | F8: C224 | G8: 43925 | H8: 0.74319213 | I8: Apr | J8: 34370 | K8: INR | L8: 6186.6 | M8: E103 | N8: E110 | O8: NA | P8: NA | Q8: =IF(J8<200000,"SE",IF(J8<500000,"AM",IF(J8<1000000,"DM",IF(J8<4500000,"SM",IF(J8>=4500000,"CM"))))) -> SE | R8: =IF(Q8="SE","AM",IF(Q8="AM","DM",IF(Q8="DM","SM",IF(Q8="SM","CM",IF(Q8="CM","CFO"))))) -> AM | S8: =VLOOKUP(M8,'Data - Employee Rights Master'!$C$3:$D$32,2,0) -> SE | T8: =VLOOKUP(N8,'Data - Employee Rights Master'!$C$3:$D$32,2,0) -> AM | U8: =IF(AND(S8=Q8,T8=R8),"PASS","DEVIATION") -> PASS | V8: =IF(J8>5000000,IF(AND(O8="Approved",P8<>"NA"),"PASS","FLAG"),"NA") -> NA | W8: =LEFT(C8,4) -> 2021 | X8: =VLOOKUP(MONTH(G8),Key!$F$3:$G$14,2,0) -> Apr | Y8: =IFERROR(IF(MATCH(F8,'Test 6'!C$5:C$9,0)>0,"RP"),"NON-RP") -> NON-RP
B9: 5 | C9: 2021C71611 | D9: 20215 | E9: CC636860 | F9: C212 | G9: 43925 | H9: 0.55947833 | I9: Apr | J9: 24190 | K9: INR | L9: 4354.2 | M9: E102 | N9: E114 | O9: NA | P9: NA | Q9: =IF(J9<200000,"SE",IF(J9<500000,"AM",IF(J9<1000000,"DM",IF(J9<4500000,"SM",IF(J9>=4500000,"CM"))))) -> SE | R9: =IF(Q9="SE","AM",IF(Q9="AM","DM",IF(Q9="DM","SM",IF(Q9="SM","CM",IF(Q9="CM","CFO"))))) -> AM | S9: =VLOOKUP(M9,'Data - Employee Rights Master'!$C$3:$D$32,2,0) -> SE | T9: =VLOOKUP(N9,'Data - Employee Rights Master'!$C$3:$D$32,2,0) -> AM | U9: =IF(AND(S9=Q9,T9=R9),"PASS","DEVIATION") -> PASS | V9: =IF(J9>5000000,IF(AND(O9="Approved",P9<>"NA"),"PASS","FLAG"),"NA") -> NA | W9: =LEFT(C9,4) -> 2021 | X9: =VLOOKUP(MONTH(G9),Key!$F$3:$G$14,2,0) -> Apr | Y9: =IFERROR(IF(MATCH(F9,'Test 6'!C$5:C$9,0)>0,"RP"),"NON-RP") -> NON-RP
B10: 6 | C10: 2021A01928 | D10: 20216 | E10: CC369548 | F10: C213 | G10: 43925 | H10: 0.55915791 | I10: Apr | J10: 4841510 | K10: INR | L10: 871471.8 | M10: E125 | N10: E126 | O10: NA | P10: NA | Q10: =IF(J10<200000,"SE",IF(J10<500000,"AM",IF(J10<1000000,"DM",IF(J10<4500000,"SM",IF(J10>=4500000,"CM"))))) -> CM | R10: =IF(Q10="SE","AM",IF(Q10="AM","DM",IF(Q10="DM","SM",IF(Q10="SM","CM",IF(Q10="CM","CFO"))))) -> CFO | S10: =VLOOKUP(M10,'Data - Employee Rights Master'!$C$3:$D$32,2,0) -> CM | T10: =VLOOKUP(N10,'Data - Employee Rights Master'!$C$3:$D$32,2,0) -> CFO | U10: =IF(AND(S10=Q10,T10=R10),"PASS","DEVIATION") -> PASS | V10: =IF(J10>5000000,IF(AND(O10="Approved",P10<>"NA"),"PASS","FLAG"),"NA") -> NA | W10: =LEFT(C10,4) -> 2021 | X10: =VLOOKUP(MONTH(G10),Key!$F$3:$G$14,2,0) -> Apr | Y10: =IFERROR(IF(MATCH(F10,'Test 6'!C$5:C$9,0)>0,"RP"),"NON-RP") -> NON-RP
B11: 7 | C11: 2021M21757 | D11: 20217 | E11: CC408705 | F11: C228 | G11: 43925 | H11: 0.67164676 | I11: Apr | J11: 469180 | K11: INR | L11: 84452.4 | M11: E112 | N11: E121 | O11: NA | P11: NA | Q11: =IF(J11<200000,"SE",IF(J11<500000,"AM",IF(J11<1000000,"DM",IF(J11<4500000,"SM",IF(J11>=4500000,"CM"))))) -> AM | R11: =IF(Q11="SE","AM",IF(Q11="AM","DM",IF(Q11="DM","SM",IF(Q11="SM","CM",IF(Q11="CM","CFO"))))) -> DM | S11: =VLOOKUP(M11,'Data - Employee Rights Master'!$C$3:$D$32,2,0) -> AM | T11: =VLOOKUP(N11,'Data - Employee Rights Master'!$C$3:$D$32,2,0) -> DM | U11: =IF(AND(S11=Q11,T11=R11),"PASS","DEVIATION") -> PASS | V11: =IF(J11>5000000,IF(AND(O11="Approved",P11<>"NA"),"PASS","FLAG"),"NA") -> NA | W11: =LEFT(C11,4) -> 2021 | X11: =VLOOKUP(MONTH(G11),Key!$F$3:$G$14,2,0) -> Apr | Y11: =IFERROR(IF(MATCH(F11,'Test 6'!C$5:C$9,0)>0,"RP"),"NON-RP") -> NON-RP
B12: 8 | C12: 2021U21062 | D12: 20218 | E12: CC396439 | F12: C242 | G12: 43928 | H12: 0.43585196 | I12: Apr | J12: 480710 | K12: INR | L12: 86527.8 | M12: E114 | N12: E120 | O12: NA | P12: NA | Q12: =IF(J12<200000,"SE",IF(J12<500000,"AM",IF(J12<1000000,"DM",IF(J12<4500000,"SM",IF(J12>=4500000,"CM"))))) -> AM | R12: =IF(Q12="SE","AM",IF(Q12="AM","DM",IF(Q12="DM","SM",IF(Q12="SM","CM",IF(Q12="CM","CFO"))))) -> DM | S12: =VLOOKUP(M12,'Data - Employee Rights Master'!$C$3:$D$32,2,0) -> AM | T12: =VLOOKUP(N12,'Data - Employee Rights Master'!$C$3:$D$32,2,0) -> DM | U12: =IF(AND(S12=Q12,T12=R12),"PASS","DEVIATION") -> PASS | V12: =IF(J12>5000000,IF(AND(O12="Approved",P12<>"NA"),"PASS","FLAG"),"NA") -> NA | W12: =LEFT(C12,4) -> 2021 | X12: =VLOOKUP(MONTH(G12),Key!$F$3:$G$14,2,0) -> Apr | Y12: =IFERROR(IF(MATCH(F12,'Test 6'!C$5:C$9,0)>0,"RP"),"NON-RP") -> NON-RP
B13: 9 | C13: 2021G01389 | D13: 20219 | E13: CC369136 | F13: C226 | G13: 43929 | H13: 0.56513168 | I13: Apr | J13: 343170 | K13: INR | L13: 61770.6 | M13: E115 | N13: E117 | O13: NA | P13: NA | Q13: =IF(J13<200000,"SE",IF(J13<500000,"AM",IF(J13<1000000,"DM",IF(J13<4500000,"SM",IF(J13>=4500000,"CM"))))) -> AM | R13: =IF(Q13="SE","AM",IF(Q13="AM","DM",IF(Q13="DM","SM",IF(Q13="SM","CM",IF(Q13="CM","CFO"))))) -> DM | S13: =VLOOKUP(M13,'Data - Employee Rights Master'!$C$3:$D$32,2,0) -> AM | T13: =VLOOKUP(N13,'Data - Employee Rights Master'!$C$3:$D$32,2,0) -> DM | U13: =IF(AND(S13=Q13,T13=R13),"PASS","DEVIATION") -> PASS | V13: =IF(J13>5000000,IF(AND(O13="Approved",P13<>"NA"),"PASS","FLAG"),"NA") -> NA | W13: =LEFT(C13,4) -> 2021 | X13: =VLOOKUP(MONTH(G13),Key!$F$3:$G$14,2,0) -> Apr | Y13: =IFERROR(IF(MATCH(F13,'Test 6'!C$5:C$9,0)>0,"RP"),"NON-RP") -> NON-RP
B14: 10 | C14: 2021O11170 | D14: 202110 | E14: CC935141 | F14: C202 | G14: 43930 | H14: 0.51491881 | I14: Apr | J14: 474940 | K14: INR | L14: 85489.2 | M14: E110 | N14: E117 | O14: NA | P14: NA | Q14: =IF(J14<200000,"SE",IF(J14<500000,"AM",IF(J14<1000000,"DM",IF(J14<4500000,"SM",IF(J14>=4500000,"CM"))))) -> AM | R14: =IF(Q14="SE","AM",IF(Q14="AM","DM",IF(Q14="DM","SM",IF(Q14="SM","CM",IF(Q14="CM","CFO"))))) -> DM | S14: =VLOOKUP(M14,'Data - Employee Rights Master'!$C$3:$D$32,2,0) -> AM | T14: =VLOOKUP(N14,'Data - Employee Rights Master'!$C$3:$D$32,2,0) -> DM | U14: =IF(AND(S14=Q14,T14=R14),"PASS","DEVIATION") -> PASS | V14: =IF(J14>5000000,IF(AND(O14="Approved",P14<>"NA"),"PASS","FLAG"),"NA") -> NA | W14: =LEFT(C14,4) -> 2021 | X14: =VLOOKUP(MONTH(G14),Key!$F$3:$G$14,2,0) -> Apr | Y14: =IFERROR(IF(MATCH(F14,'Test 6'!C$5:C$9,0)>0,"RP"),"NON-RP") -> NON-RP
B15: 11 | C15: 2021H71183 | D15: 202111 | E15: CC981153 | F15: C221 | G15: 43932 | H15: 0.64874842 | I15: Apr | J15: 50900 | K15: INR | L15: 9162 | M15: E102 | N15: E113 | O15: NA | P15: NA | Q15: =IF(J15<200000,"SE",IF(J15<500000,"AM",IF(J15<1000000,"DM",IF(J15<4500000,"SM",IF(J15>=4500000,"CM"))))) -> SE | R15: =IF(Q15="SE","AM",IF(Q15="AM","DM",IF(Q15="DM","SM",IF(Q15="SM","CM",IF(Q15="CM","CFO"))))) -> AM | S15: =VLOOKUP(M15,'Data - Employee Rights Master'!$C$3:$D$32,2,0) -> SE | T15: =VLOOKUP(N15,'Data - Employee Rights Master'!$C$3:$D$32,2,0) -> AM | U15: =IF(AND(S15=Q15,T15=R15),"PASS","DEVIATION") -> PASS | V15: =IF(J15>5000000,IF(AND(O15="Approved",P15<>"NA"),"PASS","FLAG"),"NA") -> NA | W15: =LEFT(C15,4) -> 2021 | X15: =VLOOKUP(MONTH(G15),Key!$F$3:$G$14,2,0) -> Apr | Y15: =IFERROR(IF(MATCH(F15,'Test 6'!C$5:C$9,0)>0,"RP"),"NON-RP") -> NON-RP
B16: 12 | C16: 2021A91066 | D16: 202112 | E16: CC263159 | F16: C233 | G16: 43937 | H16: 0.71044124 | I16: Apr | J16: 335080 | K16: INR | L16: 60314.4 | M16: E111 | N16: E117 | O16: NA | P16: NA | Q16: =IF(J16<200000,"SE",IF(J16<500000,"AM",IF(J16<1000000,"DM",IF(J16<4500000,"SM",IF(J16>=4500000,"CM"))))) -> AM | R16: =IF(Q16="SE","AM",IF(Q16="AM","DM",IF(Q16="DM","SM",IF(Q16="SM","CM",IF(Q16="CM","CFO"))))) -> DM | S16: =VLOOKUP(M16,'Data - Employee Rights Master'!$C$3:$D$32,2,0) -> AM | T16: =VLOOKUP(N16,'Data - Employee Rights Master'!$C$3:$D$32,2,0) -> DM | U16: =IF(AND(S16=Q16,T16=R16),"PASS","DEVIATION") -> PASS | V16: =IF(J16>5000000,IF(AND(O16="Approved",P16<>"NA"),"PASS","FLAG"),"NA") -> NA | W16: =LEFT(C16,4) -> 2021 | X16: =VLOOKUP(MONTH(G16),Key!$F$3:$G$14,2,0) -> Apr | Y16: =IFERROR(IF(MATCH(F16,'Test 6'!C$5:C$9,0)>0,"RP"),"NON-RP") -> NON-RP
... B604: 600 | C604: 2122J01328 | D604: 2122341 | E604: CC650227 | F604: C214 | G604: 44641 | H604: 0.45001946 | I604: Mar | J604: 496440 | K604: INR | L604: 89359.2 | M604: E114 | N604: E117 | O604: NA | P604: NA | Q604: =IF(J604<200000,"SE",IF(J604<500000,"AM",IF(J604<1000000,"DM",IF(J604<4500000,"SM",IF(J604>=4500000,"CM"))))) -> AM | R604: =IF(Q604="SE","AM",IF(Q604="AM","DM",IF(Q604="DM","SM",IF(Q604="SM","CM",IF(Q604="CM","CFO"))))) -> DM | S604: =VLOOKUP(M604,'Data - Employee Rights Master'!$C$3:$D$32,2,0) -> AM | T604: =VLOOKUP(N604,'Data - Employee Rights Master'!$C$3:$D$32,2,0) -> DM | U604: =IF(AND(S604=Q604,T604=R604),"PASS","DEVIATION") -> PASS | V604: =IF(J604>5000000,IF(AND(O604="Approved",P604<>"NA"),"PASS","FLAG"),"NA") -> NA | W604: =LEFT(C604,4) -> 2122 | X604: =VLOOKUP(MONTH(G604),Key!$F$3:$G$14,2,0) -> Mar | Y604: =IFERROR(IF(MATCH(F604,'Test 6'!C$5:C$9,0)>0,"RP"),"NON-RP") -> NON-RP
J606: =SUM(J5:J605) -> 480843420 | L606: =SUM(L5:L605) -> 86551816

Sheet Test 3
B2: Test 3 - Rule-based temporal analysis | S2: Test 3
B4: S. No. | C4: Transaction Id | D4: Invoice Number | E4: Unique Contract No. | F4: Customer Id | G4: Posting cum auto-invoice Generation Date | H4: Posted Timestamp | I4: Service Period | J4: Recorded Revenue | K4: Currency | L4: Tax Amount | M4: Creator Id | N4: Approver Id | O4: Board Approval | P4: Board Approval No | Q4: Day of transaction | R4: Business hours test | S4: Transaction time-screeing results | T4: Year of Revenue | U4: Month of revenue | V4: Whether RP?
B5: 1 | C5: 2021O81900 | D5: 20211 | E5: CC272485 | F5: C205 | G5: 43922 | H5: 0.43784988 | I5: Apr | J5: 483830 | K5: INR | L5: 87089.4 | M5: E115 | N5: E118 | O5: NA | P5: NA | Q5: =VLOOKUP(WEEKDAY(G5),Key!$B$3:$C$9,2,0) -> Wednesday | R5: =IF(AND(H5<TIME(18,0,0),H5>TIME(10,0,0)),"Within","Outside") -> Within | S5: =IF(OR(Q5="Sunday",R5="outside"),"Red Flag","Pass") -> Pass | T5: =IF(AND(DATE(2021,4,1)<=G5,G5<=DATE(2022,3,31)),"FY 21-22","FY 20-21") -> FY 20-21 | U5: =VLOOKUP(MONTH(G5),Key!$F$3:$G$14,2,0) -> Apr | V5: =IFERROR(IF(MATCH(F5,'Test 6'!C$5:C$9,0)>0,"RP"),"NON-RP") -> NON-RP
B6: 2 | C6: 2021M11625 | D6: 20212 | E6: CC889281 | F6: C219 | G6: 43924 | H6: 0.4213918 | I6: Apr | J6: 462100 | K6: INR | L6: 83178 | M6: E111 | N6: E117 | O6: NA | P6: NA | Q6: =VLOOKUP(WEEKDAY(G6),Key!$B$3:$C$9,2,0) -> Friday | R6: =IF(AND(H6<TIME(18,0,0),H6>TIME(10,0,0)),"Within","Outside") -> Within | S6: =IF(OR(Q6="Sunday",R6="outside"),"Red Flag","Pass") -> Pass | T6: =IF(AND(DATE(2021,4,1)<=G6,G6<=DATE(2022,3,31)),"FY 21-22","FY 20-21") -> FY 20-21 | U6: =VLOOKUP(MONTH(G6),Key!$F$3:$G$14,2,0) -> Apr | V6: =IFERROR(IF(MATCH(F6,'Test 6'!C$5:C$9,0)>0,"RP"),"NON-RP") -> NON-RP
B7: 3 | C7: 2021S01216 | D7: 20213 | E7: CC738783 | F7: C224 | G7: 43924 | H7: 0.49380763 | I7: Apr | J7: 372600 | K7: INR | L7: 67068 | M7: E116 | N7: E117 | O7: NA | P7: NA | Q7: =VLOOKUP(WEEKDAY(G7),Key!$B$3:$C$9,2,0) -> Friday | R7: =IF(AND(H7<TIME(18,0,0),H7>TIME(10,0,0)),"Within","Outside") -> Within | S7: =IF(OR(Q7="Sunday",R7="outside"),"Red Flag","Pass") -> Pass | T7: =IF(AND(DATE(2021,4,1)<=G7,G7<=DATE(2022,3,31)),"FY 21-22","FY 20-21") -> FY 20-21 | U7: =VLOOKUP(MONTH(G7),Key!$F$3:$G$14,2,0) -> Apr | V7: =IFERROR(IF(MATCH(F7,'Test 6'!C$5:C$9,0)>0,"RP"),"NON-RP") -> NON-RP
B8: 4 | C8: 2021V81178 | D8: 20214 | E8: CC797872 | F8: C224 | G8: 43925 | H8: 0.74319213 | I8: Apr | J8: 34370 | K8: INR | L8: 6186.6 | M8: E103 | N8: E110 | O8: NA | P8: NA | Q8: =VLOOKUP(WEEKDAY(G8),Key!$B$3:$C$9,2,0) -> Saturday | R8: =IF(AND(H8<TIME(18,0,0),H8>TIME(10,0,0)),"Within","Outside") -> Within | S8: =IF(OR(Q8="Sunday",R8="outside"),"Red Flag","Pass") -> Pass | T8: =IF(AND(DATE(2021,4,1)<=G8,G8<=DATE(2022,3,31)),"FY 21-22","FY 20-21") -> FY 20-21 | U8: =VLOOKUP(MONTH(G8),Key!$F$3:$G$14,2,0) -> Apr | V8: =IFERROR(IF(MATCH(F8,'Test 6'!C$5:C$9,0)>0,"RP"),"NON-RP") -> NON-RP
B9: 5 | C9: 2021C71611 | D9: 20215 | E9: CC636860 | F9: C212 | G9: 43925 | H9: 0.55947833 | I9: Apr | J9: 24190 | K9: INR | L9: 4354.2 | M9: E102 | N9: E114 | O9: NA | P9: NA | Q9: =VLOOKUP(WEEKDAY(G9),Key!$B$3:$C$9,2,0) -> Saturday | R9: =IF(AND(H9<TIME(18,0,0),H9>TIME(10,0,0)),"Within","Outside") -> Within | S9: =IF(OR(Q9="Sunday",R9="outside"),"Red Flag","Pass") -> Pass | T9: =IF(AND(DATE(2021,4,1)<=G9,G9<=DATE(2022,3,31)),"FY 21-22","FY 20-21") -> FY 20-21 | U9: =VLOOKUP(MONTH(G9),Key!$F$3:$G$14,2,0) -> Apr | V9: =IFERROR(IF(MATCH(F9,'Test 6'!C$5:C$9,0)>0,"RP"),"NON-RP") -> NON-RP
B10: 6 | C10: 2021A01928 | D10: 20216 | E10: CC369548 | F10: C213 | G10: 43925 | H10: 0.55915791 | I10: Apr | J10: 4841510 | K10: INR | L10: 871471.8 | M10: E125 | N10: E126 | O10: NA | P10: NA | Q10: =VLOOKUP(WEEKDAY(G10),Key!$B$3:$C$9,2,0) -> Saturday | R10: =IF(AND(H10<TIME(18,0,0),H10>TIME(10,0,0)),"Within","Outside") -> Within | S10: =IF(OR(Q10="Sunday",R10="outside"),"Red Flag","Pass") -> Pass | T10: =IF(AND(DATE(2021,4,1)<=G10,G10<=DATE(2022,3,31)),"FY 21-22","FY 20-21") -> FY 20-21 | U10: =VLOOKUP(MONTH(G10),Key!$F$3:$G$14,2,0) -> Apr | V10: =IFERROR(IF(MATCH(F10,'Test 6'!C$5:C$9,0)>0,"RP"),"NON-RP") -> NON-RP
B11: 7 | C11: 2021M21757 | D11: 20217 | E11: CC408705 | F11: C228 | G11: 43925 | H11: 0.67164676 | I11: Apr | J11: 469180 | K11: INR | L11: 84452.4 | M11: E112 | N11: E121 | O11: NA | P11: NA | Q11: =VLOOKUP(WEEKDAY(G11),Key!$B$3:$C$9,2,0) -> Saturday | R11: =IF(AND(H11<TIME(18,0,0),H11>TIME(10,0,0)),"Within","Outside") -> Within | S11: =IF(OR(Q11="Sunday",R11="outside"),"Red Flag","Pass") -> Pass | T11: =IF(AND(DATE(2021,4,1)<=G11,G11<=DATE(2022,3,31)),"FY 21-22","FY 20-21") -> FY 20-21 | U11: =VLOOKUP(MONTH(G11),Key!$F$3:$G$14,2,0) -> Apr | V11: =IFERROR(IF(MATCH(F11,'Test 6'!C$5:C$9,0)>0,"RP"),"NON-RP") -> NON-RP
B12: 8 | C12: 2021U21062 | D12: 20218 | E12: CC396439 | F12: C242 | G12: 43928 | H12: 0.43585196 | I12: Apr | J12: 480710 | K12: INR | L12: 86527.8 | M12: E114 | N12: E120 | O12: NA | P12: NA | Q12: =VLOOKUP(WEEKDAY(G12),Key!$B$3:$C$9,2,0) -> Tuesday | R12: =IF(AND(H12<TIME(18,0,0),H12>TIME(10,0,0)),"Within","Outside") -> Within | S12: =IF(OR(Q12="Sunday",R12="outside"),"Red Flag","Pass") -> Pass | T12: =IF(AND(DATE(2021,4,1)<=G12,G12<=DATE(2022,3,31)),"FY 21-22","FY 20-21") -> FY 20-21 | U12: =VLOOKUP(MONTH(G12),Key!$F$3:$G$14,2,0) -> Apr | V12: =IFERROR(IF(MATCH(F12,'Test 6'!C$5:C$9,0)>0,"RP"),"NON-RP") -> NON-RP
B13: 9 | C13: 2021G01389 | D13: 20219 | E13: CC369136 | F13: C226 | G13: 43929 | H13: 0.56513168 | I13: Apr | J13: 343170 | K13: INR | L13: 61770.6 | M13: E115 | N13: E117 | O13: NA | P13: NA | Q13: =VLOOKUP(WEEKDAY(G13),Key!$B$3:$C$9,2,0) -> Wednesday | R13: =IF(AND(H13<TIME(18,0,0),H13>TIME(10,0,0)),"Within","Outside") -> Within | S13: =IF(OR(Q13="Sunday",R13="outside"),"Red Flag","Pass") -> Pass | T13: =IF(AND(DATE(2021,4,1)<=G13,G13<=DATE(2022,3,31)),"FY 21-22","FY 20-21") -> FY 20-21 | U13: =VLOOKUP(MONTH(G13),Key!$F$3:$G$14,2,0) -> Apr | V13: =IFERROR(IF(MATCH(F13,'Test 6'!C$5:C$9,0)>0,"RP"),"NON-RP") -> NON-RP
B14: 10 | C14: 2021O11170 | D14: 202110 | E14: CC935141 | F14: C202 | G14: 43930 | H14: 0.51491881 | I14: Apr | J14: 474940 | K14: INR | L14: 85489.2 | M14: E110 | N14: E117 | O14: NA | P14: NA | Q14: =VLOOKUP(WEEKDAY(G14),Key!$B$3:$C$9,2,0) -> Thursday | R14: =IF(AND(H14<TIME(18,0,0),H14>TIME(10,0,0)),"Within","Outside") -> Within | S14: =IF(OR(Q14="Sunday",R14="outside"),"Red Flag","Pass") -> Pass | T14: =IF(AND(DATE(2021,4,1)<=G14,G14<=DATE(2022,3,31)),"FY 21-22","FY 20-21") -> FY 20-21 | U14: =VLOOKUP(MONTH(G14),Key!$F$3:$G$14,2,0) -> Apr | V14: =IFERROR(IF(MATCH(F14,'Test 6'!C$5:C$9,0)>0,"RP"),"NON-RP") -> NON-RP
B15: 11 | C15: 2021H71183 | D15: 202111 | E15: CC981153 | F15: C221 | G15: 43932 | H15: 0.64874842 | I15: Apr | J15: 50900 | K15: INR | L15: 9162 | M15: E102 | N15: E113 | O15: NA | P15: NA | Q15: =VLOOKUP(WEEKDAY(G15),Key!$B$3:$C$9,2,0) -> Saturday | R15: =IF(AND(H15<TIME(18,0,0),H15>TIME(10,0,0)),"Within","Outside") -> Within | S15: =IF(OR(Q15="Sunday",R15="outside"),"Red Flag","Pass") -> Pass | T15: =IF(AND(DATE(2021,4,1)<=G15,G15<=DATE(2022,3,31)),"FY 21-22","FY 20-21") -> FY 20-21 | U15: =VLOOKUP(MONTH(G15),Key!$F$3:$G$14,2,0) -> Apr | V15: =IFERROR(IF(MATCH(F15,'Test 6'!C$5:C$9,0)>0,"RP"),"NON-RP") -> NON-RP
B16: 12 | C16: 2021A91066 | D16: 202112 | E16: CC263159 | F16: C233 | G16: 43937 | H16: 0.71044124 | I16: Apr | J16: 335080 | K16: INR | L16: 60314.4 | M16: E111 | N16: E117 | O16: NA | P16: NA | Q16: =VLOOKUP(WEEKDAY(G16),Key!$B$3:$C$9,2,0) -> Thursday | R16: =IF(AND(H16<TIME(18,0,0),H16>TIME(10,0,0)),"Within","Outside") -> Within | S16: =IF(OR(Q16="Sunday",R16="outside"),"Red Flag","Pass") -> Pass | T16: =IF(AND(DATE(2021,4,1)<=G16,G16<=DATE(2022,3,31)),"FY 21-22","FY 20-21") -> FY 20-21 | U16: =VLOOKUP(MONTH(G16),Key!$F$3:$G$14,2,0) -> Apr | V16: =IFERROR(IF(MATCH(F16,'Test 6'!C$5:C$9,0)>0,"RP"),"NON-RP") -> NON-RP
... B604: 600 | C604: 2122J01328 | D604: 2122341 | E604: CC650227 | F604: C214 | G604: 44641 | H604: 0.45001946 | I604: Mar | J604: 496440 | K604: INR | L604: 89359.2 | M604: E114 | N604: E117 | O604: NA | P604: NA | Q604: =VLOOKUP(WEEKDAY(G604),Key!$B$3:$C$9,2,0) -> Monday | R604: =IF(AND(H604<TIME(18,0,0),H604>TIME(10,0,0)),"Within","Outside") -> Within | S604: =IF(OR(Q604="Sunday",R604="outside"),"Red Flag","Pass") -> Pass | T604: =IF(AND(DATE(2021,4,1)<=G604,G604<=DATE(2022,3,31)),"FY 21-22","FY 20-21") -> FY 21-22 | U604: =VLOOKUP(MONTH(G604),Key!$F$3:$G$14,2,0) -> Mar | V604: =IFERROR(IF(MATCH(F604,'Test 6'!C$5:C$9,0)>0,"RP"),"NON-RP") -> NON-RP
J606: =SUM(J5:J605) -> 480843420 | L606: =SUM(L5:L605) -> 86551816
B608: Red Flag entries in transaction time-screeing (Test 3)
B609: S. No. | C609: Transaction Id | D609: Invoice Number | E609: Unique Contract No. | F609: Customer Id | G609: Invoice Date | H609: Posted Timestamp | I609: Service Period | J609: Recorded Revenue | K609: Currency | L609: Tax Amount | M609: Creator Id | N609: Approver Id | P609: 0 | Q609: Creator Limits Reperformed | R609: Approval Limits Reperformed | S609: Current Creator | T609: Current Approver | U609: Limits test | V609: Day of transaction | W609: Business hours test | X609: Time series results | Y609: Year of Revenue | Z609: Month of revenue
B610: 302 | C610: 2122R81752 | D610: 212243 | E610: CC714760 | F610: C239 | G610: 44325 | H610: 0.49611111 | I610: May | J610: 4279450 | K610: INR | L610: 770040 | M610: E123 | N610: E125 | Q610: =IF(J610<200000,"SE",IF(J610<500000,"AM",IF(J610<1000000,"DM",IF(J610<4500000,"SM",IF(J610>4500000,"CM"))))) -> SM | R610: =IF(Q610="SE","AM",IF(Q610="AM","DM",IF(Q610="DM","SM",IF(Q610="SM","CM",IF(Q610="CM","CFO"))))) -> CM | S610: =VLOOKUP(M610,'Data - Employee Rights Master'!$C$3:$D$32,2,0) -> SM | T610: =VLOOKUP(N610,'Data - Employee Rights Master'!$C$3:$D$32,2,0) -> CM | U610: =IF(AND(S610=Q610,T610=R610),"PASS","DEVIATION") -> PASS | V610: =VLOOKUP(WEEKDAY(G610),Key!$B$3:$C$9,2,0) -> Sunday | W610: =IF(AND(H610<TIME(18,0,0),H610>TIME(10,0,0)),"Within","Outside") -> Within | X610: =IF(OR(V610="Sunday",W610="outside"),"Red Flag","Pass") -> Red Flag | Y610: =LEFT(C610,4) -> 2122 | Z610: =VLOOKUP(MONTH(G610),Key!$F$3:$G$14,2,0) -> May
B611: 312 | C611: 2122C71512 | D611: 212253 | E611: CC464231 | F611: C239 | G611: 44332 | H611: 0.52202546 | I611: May | J611: 4951880 | K611: INR | L611: 891000 | M611: E125 | N611: E126 | Q611: =IF(J611<200000,"SE",IF(J611<500000,"AM",IF(J611<1000000,"DM",IF(J611<4500000,"SM",IF(J611>4500000,"CM"))))) -> CM | R611: =IF(Q611="SE","AM",IF(Q611="AM","DM",IF(Q611="DM","SM",IF(Q611="SM","CM",IF(Q611="CM","CFO"))))) -> CFO | S611: =VLOOKUP(M611,'Data - Employee Rights Master'!$C$3:$D$32,2,0) -> CM | T611: =VLOOKUP(N611,'Data - Employee Rights Master'!$C$3:$D$32,2,0) -> CFO | U611: =IF(AND(S611=Q611,T611=R611),"PASS","DEVIATION") -> PASS | V611: =VLOOKUP(WEEKDAY(G611),Key!$B$3:$C$9,2,0) -> Sunday | W611: =IF(AND(H611<TIME(18,0,0),H611>TIME(10,0,0)),"Within","Outside") -> Within | X611: =IF(OR(V611="Sunday",W611="outside"),"Red Flag","Pass") -> Red Flag | Y611: =LEFT(C611,4) -> 2122 | Z611: =VLOOKUP(MONTH(G611),Key!$F$3:$G$14,2,0) -> May
B612: 320 | C612: 2122S11948 | D612: 212261 | E612: CC551324 | F612: C240 | G612: 44339 | H612: 0.44253472 | I612: May | J612: 4062620 | K612: INR | L612: 730800 | M612: E123 | N612: E125 | Q612: =IF(J612<200000,"SE",IF(J612<500000,"AM",IF(J612<1000000,"DM",IF(J612<4500000,"SM",IF(J612>4500000,"CM"))))) -> SM | R612: =IF(Q612="SE","AM",IF(Q612="AM","DM",IF(Q612="DM","SM",IF(Q612="SM","CM",IF(Q612="CM","CFO"))))) -> CM | S612: =VLOOKUP(M612,'Data - Employee Rights Master'!$C$3:$D$32,2,0) -> SM | T612: =VLOOKUP(N612,'Data - Employee Rights Master'!$C$3:$D$32,2,0) -> CM | U612: =IF(AND(S612=Q612,T612=R612),"PASS","DEVIATION") -> PASS | V612: =VLOOKUP(WEEKDAY(G612),Key!$B$3:$C$9,2,0) -> Sunday | W612: =IF(AND(H612<TIME(18,0,0),H612>TIME(10,0,0)),"Within","Outside") -> Within | X612: =IF(OR(V612="Sunday",W612="outside"),"Red Flag","Pass") -> Red Flag | Y612: =LEFT(C612,4) -> 2122 | Z612: =VLOOKUP(MONTH(G612),Key!$F$3:$G$14,2,0) -> May
B613: 321 | C613: 2122T61344 | D613: 212262 | E613: CC117699 | F613: C240 | G613: 44338 | H613: 0.81618056 | I613: May | J613: 4672170 | K613: INR | L613: 840780 | M613: E125 | N613: E126 | Q613: =IF(J613<200000,"SE",IF(J613<500000,"AM",IF(J613<1000000,"DM",IF(J613<4500000,"SM",IF(J613>4500000,"CM"))))) -> CM | R613: =IF(Q613="SE","AM",IF(Q613="AM","DM",IF(Q613="DM","SM",IF(Q613="SM","CM",IF(Q613="CM","CFO"))))) -> CFO | S613: =VLOOKUP(M613,'Data - Employee Rights Master'!$C$3:$D$32,2,0) -> CM | T613: =VLOOKUP(N613,'Data - Employee Rights Master'!$C$3:$D$32,2,0) -> CFO | U613: =IF(AND(S613=Q613,T613=R613),"PASS","DEVIATION") -> PASS | V613: =VLOOKUP(WEEKDAY(G613),Key!$B$3:$C$9,2,0) -> Saturday | W613: =IF(AND(H613<TIME(18,0,0),H613>TIME(10,0,0)),"Within","Outside") -> Outside | X613: =IF(OR(V613="Sunday",W613="outside"),"Red Flag","Pass") -> Red Flag | Y613: =LEFT(C613,4) -> 2122 | Z613: =VLOOKUP(MONTH(G613),Key!$F$3:$G$14,2,0) -> May
B614: 328 | C614: 2122K21518 | D614: 212269 | E614: CC609741 | F614: C236 | G614: 44345 | H614: 0.82333333 | I614: May | J614: 4611710 | K614: INR | L614: 829800 | M614: E125 | N614: E126 | Q614: =IF(J614<200000,"SE",IF(J614<500000,"AM",IF(J614<1000000,"DM",IF(J614<4500000,"SM",IF(J614>4500000,"CM"))))) -> CM | R614: =IF(Q614="SE","AM",IF(Q614="AM","DM",IF(Q614="DM","SM",IF(Q614="SM","CM",IF(Q614="CM","CFO"))))) -> CFO | S614: =VLOOKUP(M614,'Data - Employee Rights Master'!$C$3:$D$32,2,0) -> CM | T614: =VLOOKUP(N614,'Data - Employee Rights Master'!$C$3:$D$32,2,0) -> CFO | U614: =IF(AND(S614=Q614,T614=R614),"PASS","DEVIATION") -> PASS | V614: =VLOOKUP(WEEKDAY(G614),Key!$B$3:$C$9,2,0) -> Saturday | W614: =IF(AND(H614<TIME(18,0,0),H614>TIME(10,0,0)),"Within","Outside") -> Outside | X614: =IF(OR(V614="Sunday",W614="outside"),"Red Flag","Pass") -> Red Flag | Y614: =LEFT(C614,4) -> 2122 | Z614: =VLOOKUP(MONTH(G614),Key!$F$3:$G$14,2,0) -> May
B615: 335 | C615: 2122D91262 | D615: 212276 | E615: CC889005 | F615: C236 | G615: 44353 | H615: 0.57105324 | I615: Jun | J615: 4080130 | K615: INR | L615: 734400 | M615: E124 | N615: E125 | Q615: =IF(J615<200000,"SE",IF(J615<500000,"AM",IF(J615<1000000,"DM",IF(J615<4500000,"SM",IF(J615>4500000,"CM"))))) -> SM | R615: =IF(Q615="SE","AM",IF(Q615="AM","DM",IF(Q615="DM","SM",IF(Q615="SM","CM",IF(Q615="CM","CFO"))))) -> CM | S615: =VLOOKUP(M615,'Data - Employee Rights Master'!$C$3:$D$32,2,0) -> SM | T615: =VLOOKUP(N615,'Data - Employee Rights Master'!$C$3:$D$32,2,0) -> CM | U615: =IF(AND(S615=Q615,T615=R615),"PASS","DEVIATION") -> PASS | V615: =VLOOKUP(WEEKDAY(G615),Key!$B$3:$C$9,2,0) -> Sunday | W615: =IF(AND(H615<TIME(18,0,0),H615>TIME(10,0,0)),"Within","Outside") -> Within | X615: =IF(OR(V615="Sunday",W615="outside"),"Red Flag","Pass") -> Red Flag | Y615: =LEFT(C615,4) -> 2122 | Z615: =VLOOKUP(MONTH(G615),Key!$F$3:$G$14,2,0) -> Jun
B616: 349 | C616: 2122J41040 | D616: 212290 | E616: CC758767 | F616: C240 | G616: 44373 | H616: 0.814375 | I616: Jun | J616: 4330520 | K616: INR | L616: 779400 | M616: E123 | N616: E125 | Q616: =IF(J616<200000,"SE",IF(J616<500000,"AM",IF(J616<1000000,"DM",IF(J616<4500000,"SM",IF(J616>4500000,"CM"))))) -> SM | R616: =IF(Q616="SE","AM",IF(Q616="AM","DM",IF(Q616="DM","SM",IF(Q616="SM","CM",IF(Q616="CM","CFO"))))) -> CM | S616: =VLOOKUP(M616,'Data - Employee Rights Master'!$C$3:$D$32,2,0) -> SM | T616: =VLOOKUP(N616,'Data - Employee Rights Master'!$C$3:$D$32,2,0) -> CM | U616: =IF(AND(S616=Q616,T616=R616),"PASS","DEVIATION") -> PASS | V616: =VLOOKUP(WEEKDAY(G616),Key!$B$3:$C$9,2,0) -> Saturday | W616: =IF(AND(H616<TIME(18,0,0),H616>TIME(10,0,0)),"Within","Outside") -> Outside | X616: =IF(OR(V616="Sunday",W616="outside"),"Red Flag","Pass") -> Red Flag | Y616: =LEFT(C616,4) -> 2122 | Z616: =VLOOKUP(MONTH(G616),Key!$F$3:$G$14,2,0) -> Jun
B617: 353 | C617: 2122R41764 | D617: 212294 | E617: CC958168 | F617: C236 | G617: 44381 | H617: 0.49063657 | I617: Jul | J617: 4673740 | K617: INR | L617: 841140 | M617: E125 | N617: E126 | Q617: =IF(J617<200000,"SE",IF(J617<500000,"AM",IF(J617<1000000,"DM",IF(J617<4500000,"SM",IF(J617>4500000,"CM"))))) -> CM | R617: =IF(Q617="SE","AM",IF(Q617="AM","DM",IF(Q617="DM","SM",IF(Q617="SM","CM",IF(Q617="CM","CFO"))))) -> CFO | S617: =VLOOKUP(M617,'Data - Employee Rights Master'!$C$3:$D$32,2,0) -> CM | T617: =VLOOKUP(N617,'Data - Employee Rights Master'!$C$3:$D$32,2,0) -> CFO | U617: =IF(AND(S617=Q617,T617=R617),"PASS","DEVIATION") -> PASS | V617: =VLOOKUP(WEEKDAY(G617),Key!$B$3:$C$9,2,0) -> Sunday | W617: =IF(AND(H617<TIME(18,0,0),H617>TIME(10,0,0)),"Within","Outside") -> Within | X617: =IF(OR(V617="Sunday",W617="outside"),"Red Flag","Pass") -> Red Flag | Y617: =LEFT(C617,4) -> 2122 | Z617: =VLOOKUP(MONTH(G617),Key!$F$3:$G$14,2,0) -> Jul
B618: 363 | C618: 2122O71438 | D618: 2122104 | E618: CC504719 | F618: C240 | G618: 44388 | H618: 0.50436343 | I618: Jul | J618: 4059510 | K618: INR | L618: 730440 | M618: E123 | N618: E125 | Q618: =IF(J618<200000,"SE",IF(J618<500000,"AM",IF(J618<1000000,"DM",IF(J618<4500000,"SM",IF(J618>4500000,"CM"))))) -> SM | R618: =IF(Q618="SE","AM",IF(Q618="AM","DM",IF(Q618="DM","SM",IF(Q618="SM","CM",IF(Q618="CM","CFO"))))) -> CM | S618: =VLOOKUP(M618,'Data - Employee Rights Master'!$C$3:$D$32,2,0) -> SM | T618: =VLOOKUP(N618,'Data - Employee Rights Master'!$C$3:$D$32,2,0) -> CM | U618: =IF(AND(S618=Q618,T618=R618),"PASS","DEVIATION") -> PASS | V618: =VLOOKUP(WEEKDAY(G618),Key!$B$3:$C$9,2,0) -> Sunday | W618: =IF(AND(H618<TIME(18,0,0),H618>TIME(10,0,0)),"Within","Outside") -> Within | X618: =IF(OR(V618="Sunday",W618="outside"),"Red Flag","Pass") -> Red Flag | Y618: =LEFT(C618,4) -> 2122 | Z618: =VLOOKUP(MONTH(G618),Key!$F$3:$G$14,2,0) -> Jul
B619: 379 | C619: 2122E11145 | D619: 2122120 | E619: CC483508 | F619: C240 | G619: 44395 | H619: 0.50341665 | I619: Jul | J619: 4211080 | K619: INR | L619: 757800 | M619: E124 | N619: E125 | Q619: =IF(J619<200000,"SE",IF(J619<500000,"AM",IF(J619<1000000,"DM",IF(J619<4500000,"SM",IF(J619>4500000,"CM"))))) -> SM | R619: =IF(Q619="SE","AM",IF(Q619="AM","DM",IF(Q619="DM","SM",IF(Q619="SM","CM",IF(Q619="CM","CFO"))))) -> CM | S619: =VLOOKUP(M619,'Data - Employee Rights Master'!$C$3:$D$32,2,0) -> SM | T619: =VLOOKUP(N619,'Data - Employee Rights Master'!$C$3:$D$32,2,0) -> CM | U619: =IF(AND(S619=Q619,T619=R619),"PASS","DEVIATION") -> PASS | V619: =VLOOKUP(WEEKDAY(G619),Key!$B$3:$C$9,2,0) -> Sunday | W619: =IF(AND(H619<TIME(18,0,0),H619>TIME(10,0,0)),"Within","Outside") -> Within | X619: =IF(OR(V619="Sunday",W619="outside"),"Red Flag","Pass") -> Red Flag | Y619: =LEFT(C619,4) -> 2122 | Z619: =VLOOKUP(MONTH(G619),Key!$F$3:$G$14,2,0) -> Jul
B620: 394 | C620: 2122Q91600 | D620: 2122135 | E620: CC158828 | F620: C240 | G620: 44415 | H620: 0.80775463 | I620: Aug | J620: 4250210 | K620: INR | L620: 764820 | M620: E123 | N620: E125 | Q620: =IF(J620<200000,"SE",IF(J620<500000,"AM",IF(J620<1000000,"DM",IF(J620<4500000,"SM",IF(J620>4500000,"CM"))))) -> SM | R620: =IF(Q620="SE","AM",IF(Q620="AM","DM",IF(Q620="DM","SM",IF(Q620="SM","CM",IF(Q620="CM","CFO"))))) -> CM | S620: =VLOOKUP(M620,'Data - Employee Rights Master'!$C$3:$D$32,2,0) -> SM | T620: =VLOOKUP(N620,'Data - Employee Rights Master'!$C$3:$D$32,2,0) -> CM | U620: =IF(AND(S620=Q620,T620=R620),"PASS","DEVIATION") -> PASS | V620: =VLOOKUP(WEEKDAY(G620),Key!$B$3:$C$9,2,0) -> Saturday | W620: =IF(AND(H620<TIME(18,0,0),H620>TIME(10,0,0)),"Within","Outside") -> Outside | X620: =IF(OR(V620="Sunday",W620="outside"),"Red Flag","Pass") -> Red Flag | Y620: =LEFT(C620,4) -> 2122 | Z620: =VLOOKUP(MONTH(G620),Key!$F$3:$G$14,2,0) -> Aug
B621: 407 | C621: 2122U71686 | D621: 2122148 | E621: CC859081 | F621: C239 | G621: 44423 | H621: 0.46967499 | I621: Aug | J621: 4927020 | K621: INR | L621: 886500 | M621: E125 | N621: E126 | Q621: =IF(J621<200000,"SE",IF(J621<500000,"AM",IF(J621<1000000,"DM",IF(J621<4500000,"SM",IF(J621>4500000,"CM"))))) -> CM | R621: =IF(Q621="SE","AM",IF(Q621="AM","DM",IF(Q621="DM","SM",IF(Q621="SM","CM",IF(Q621="CM","CFO"))))) -> CFO | S621: =VLOOKUP(M621,'Data - Employee Rights Master'!$C$3:$D$32,2,0) -> CM | T621: =VLOOKUP(N621,'Data - Employee Rights Master'!$C$3:$D$32,2,0) -> CFO | U621: =IF(AND(S621=Q621,T621=R621),"PASS","DEVIATION") -> PASS | V621: =VLOOKUP(WEEKDAY(G621),Key!$B$3:$C$9,2,0) -> Sunday | W621: =IF(AND(H621<TIME(18,0,0),H621>TIME(10,0,0)),"Within","Outside") -> Within | X621: =IF(OR(V621="Sunday",W621="outside"),"Red Flag","Pass") -> Red Flag | Y621: =LEFT(C621,4) -> 2122 | Z621: =VLOOKUP(MONTH(G621),Key!$F$3:$G$14,2,0) -> Aug
... B636: 540 | C636: 2122W81761 | D636: 2122281 | E636: CC672893 | F636: C239 | G636: 44583 | H636: 0.80902778 | I636: Jan | J636: 4651520 | K636: INR | L636: 836820 | M636: E125 | N636: E126 | Q636: =IF(J636<200000,"SE",IF(J636<500000,"AM",IF(J636<1000000,"DM",IF(J636<4500000,"SM",IF(J636>4500000,"CM"))))) -> CM | R636: =IF(Q636="SE","AM",IF(Q636="AM","DM",IF(Q636="DM","SM",IF(Q636="SM","CM",IF(Q636="CM","CFO"))))) -> CFO | S636: =VLOOKUP(M636,'Data - Employee Rights Master'!$C$3:$D$32,2,0) -> CM | T636: =VLOOKUP(N636,'Data - Employee Rights Master'!$C$3:$D$32,2,0) -> CFO | U636: =IF(AND(S636=Q636,T636=R636),"PASS","DEVIATION") -> PASS | V636: =VLOOKUP(WEEKDAY(G636),Key!$B$3:$C$9,2,0) -> Saturday | W636: =IF(AND(H636<TIME(18,0,0),H636>TIME(10,0,0)),"Within","Outside") -> Outside | X636: =IF(OR(V636="Sunday",W636="outside"),"Red Flag","Pass") -> Red Flag | Y636: =LEFT(C636,4) -> 2122 | Z636: =VLOOKUP(MONTH(G636),Key!$F$3:$G$14,2,0) -> Jan

Sheet Test 4
A2: 4 | B2: Revenue Summary - Trend (Test 4)
B3: Year-wise trend Analysis (Test 4)
C4: FY 2020-21 | D4: =SUMIF('Test 1,2'!$W$5:$W$604,2021,'Test 1,2'!$J$5:$J$604) -> 158936380
C5: FY 2021-22 | D5: =SUMIF('Test 1,2'!$W$5:$W$604,2122,'Test 1,2'!$J$5:$J$604) -> 321907040
D6: =SUM(D4:D5) -> 480843420
C8: Increase | D8: =(D5-D4)/D4 -> 1.025383 | E8: Significant increase is observed
B12: Concerns in Month wise trend analysis (Test 4)
F13: % Change in recorded revenue | G13: % Change in no of transactions
E14: No of times change is approx. 40% | F14: =COUNTIF(F20:F44,">39%")+COUNTIF(F20:F44,"<-39%") -> 15 | G14: =COUNTIF(G20:G44,">39%")+COUNTIF(G20:G44,"<-39%") -> 8
C17: Row Labels | D17: Sum of Recorded Revenue | E17: Count of Recorded Revenue2 | F17: % Change in recorded revenue | G17: % Change in no of transactions
C18: 2020
C19: Apr | D19: 11081560 | E19: 20
C20: May | D20: 18374380 | E20: 27 | F20: =(D20-D19)/D19 -> 0.65810409 | G20: =(E20-E19)/E19 -> 0.35
C21: Jun | D21: 16719590 | E21: 22 | F21: =(D21-D20)/D20 -> -0.090059637 | G21: =(E21-E20)/E20 -> -0.18518519
C22: Jul | D22: 19592030 | E22: 27 | F22: =(D22-D21)/D21 -> 0.17180086 | G22: =(E22-E21)/E21 -> 0.22727273
C23: Aug | D23: 12799820 | E23: 20 | F23: =(D23-D22)/D22 -> -0.3466823 | G23: =(E23-E22)/E22 -> -0.25925926
C24: Sep | D24: 10538630 | E24: 30 | F24: =(D24-D23)/D23 -> -0.17665795 | G24: =(E24-E23)/E23 -> 0.5
C25: Oct | D25: 12037390 | E25: 22 | F25: =(D25-D24)/D24 -> 0.14221583 | G25: =(E25-E24)/E24 -> -0.26666667
C26: Nov | D26: 6395660 | E26: 20 | F26: =(D26-D25)/D25 -> -0.46868383 | G26: =(E26-E25)/E25 -> -0.090909091
C27: Dec | D27: 25887420 | E27: 16 | F27: =(D27-D26)/D26 -> 3.0476542 | G27: =(E27-E26)/E26 -> -0.2
C28: 2021
C29: Jan | D29: 5776500 | E29: 16 | F29: =(D29-D27)/D27 -> -0.77686073 | G29: =(E29-E27)/E27 -> 0
C30: Feb | D30: 13132750 | E30: 19 | F30: =(D30-D29)/D29 -> 1.2734788 | G30: =(E30-E29)/E29 -> 0.1875
C31: Mar | D31: 6600650 | E31: 20 | F31: =(D31-D30)/D30 -> -0.49739011 | G31: =(E31-E30)/E30 -> 0.052631579
C32: Apr | D32: 20795250 | E32: 34 | F32: =(D32-D31)/D31 -> 2.1504852 | G32: =(E32-E31)/E31 -> 0.7
C33: May | D33: 30331170 | E33: 37 | F33: =(D33-D32)/D32 -> 0.45856241 | G33: =(E33-E32)/E32 -> 0.088235294
C34: Jun | D34: 17522090 | E34: 22 | F34: =(D34-D33)/D33 -> -0.42230748 | G34: =(E34-E33)/E33 -> -0.40540541
C35: Jul | D35: 58728270 | E35: 36 | F35: =(D35-D34)/D34 -> 2.3516704 | G35: =(E35-E34)/E34 -> 0.63636364
C36: Aug | D36: 46056320 | E36: 40 | F36: =(D36-D35)/D35 -> -0.21577257 | G36: =(E36-E35)/E35 -> 0.11111111
C37: Sep | D37: 16966840 | E37: 13 | F37: =(D37-D36)/D36 -> -0.63160669 | G37: =(E37-E36)/E36 -> -0.675
C38: Oct | D38: 8868660 | E38: 24 | F38: =(D38-D37)/D37 -> -0.47729453 | G38: =(E38-E37)/E37 -> 0.84615385
C39: Nov | D39: 32091340 | E39: 24 | F39: =(D39-D38)/D38 -> 2.6185106 | G39: =(E39-E38)/E38 -> 0
C40: Dec | D40: 40817150 | E40: 34 | F40: =(D40-D39)/D39 -> 0.27190544 | G40: =(E40-E39)/E39 -> 0.41666667
C41: 2022
C42: Jan | D42: 32062340 | E42: 32 | F42: =(D42-D40)/D40 -> -0.21448852 | G42: =(E42-E40)/E40 -> -0.058823529
C43: Feb | D43: 12746590 | E43: 28 | F43: =(D43-D42)/D42 -> -0.60244355 | G43: =(E43-E42)/E42 -> -0.125
C44: Mar | D44: 4921020 | E44: 17 | F44: =(D44-D43)/D43 -> -0.61393439 | G44: =(E44-E43)/E43 -> -0.39285714
C45: Grand Total | D45: 480843420 | E45: 600

Sheet Test 5
A2: 5 | B2: Revenue Spread - Pre-IPO Revenue-Window and Near-Threshold Analysis (Test 5)
E4: As per company policies, rupees 50,00,000 is the limit to get Board approval
C21: Observation - Unusual clusters detected near to board approval limit and that is around within a year before IPO date
C24: Row Labels | D24: Count of Time-Screen test
C25: Pass | D25: 15
C26: Red Flag | D26: 27
C27: Grand Total | D27: 42
C29: Summary of transactions in 40L to 50L range(Test 5)
C30: S. No. | D30: Transaction Id | E30: Unique Contract No. | F30: Customer Id | G30: Invoice Date | H30: Recorded Revenue | I30: Creator Id | J30: Approver Id | K30: Time-Screen test
C31: 6 | D31: 2021A01928 | E31: CC369548 | F31: C213 | G31: 43925 | H31: 4841510 | I31: E125 | J31: E126 | K31: =VLOOKUP(E31,'Test 3'!$E$4:$S$604,15,0) -> Pass
C32: 28 | D32: 2021B41966 | E32: CC731431 | F32: C239 | G32: 43958 | H32: 4762260 | I32: E125 | J32: E126 | K32: =VLOOKUP(E32,'Test 3'!$E$4:$S$604,15,0) -> Pass
C33: 72 | D33: 2021T91070 | E33: CC651707 | F33: C202 | G33: 44019 | H33: 4374900 | I33: E124 | J33: E125 | K33: =VLOOKUP(E33,'Test 3'!$E$4:$S$604,15,0) -> Pass
C34: 154 | D34: 2021U91067 | E34: CC625217 | F34: C215 | G34: 44116 | H34: 4699400 | I34: E125 | J34: E126 | K34: =VLOOKUP(E34,'Test 3'!$E$4:$S$604,15,0) -> Pass
C35: 302 | D35: 2122R81752 | E35: CC714760 | F35: C239 | G35: 44325 | H35: 4279450 | I35: E123 | J35: E125 | K35: =VLOOKUP(E35,'Test 3'!$E$4:$S$604,15,0) -> Red Flag
C36: 312 | D36: 2122C71512 | E36: CC464231 | F36: C239 | G36: 44332 | H36: 4951880 | I36: E125 | J36: E126 | K36: =VLOOKUP(E36,'Test 3'!$E$4:$S$604,15,0) -> Red Flag
C37: 320 | D37: 2122S11948 | E37: CC551324 | F37: C240 | G37: 44339 | H37: 4062620 | I37: E123 | J37: E125 | K37: =VLOOKUP(E37,'Test 3'!$E$4:$S$604,15,0) -> Red Flag
C38: 321 | D38: 2122T61344 | E38: CC117699 | F38: C240 | G38: 44338 | H38: 4672170 | I38: E125 | J38: E126 | K38: =VLOOKUP(E38,'Test 3'!$E$4:$S$604,15,0) -> Red Flag
C39: 328 | D39: 2122K21518 | E39: CC609741 | F39: C236 | G39: 44345 | H39: 4611710 | I39: E125 | J39: E126 | K39: =VLOOKUP(E39,'Test 3'!$E$4:$S$604,15,0) -> Red Flag
C40: 335 | D40: 2122D91262 | E40: CC889005 | F40: C236 | G40: 44353 | H40: 4080130 | I40: E124 | J40: E125 | K40: =VLOOKUP(E40,'Test 3'!$E$4:$S$604,15,0) -> Red Flag
C41: 349 | D41: 2122J41040 | E41: CC758767 | F41: C240 | G41: 44373 | H41: 4330520 | I41: E123 | J41: E125 | K41: =VLOOKUP(E41,'Test 3'!$E$4:$S$604,15,0) -> Red Flag
C42: 353 | D42: 2122R41764 | E42: CC958168 | F42: C236 | G42: 44381 | H42: 4673740 | I42: E125 | J42: E126 | K42: =VLOOKUP(E42,'Test 3'!$E$4:$S$604,15,0) -> Red Flag
... C72: 575 | D72: 2122D81367 | E72: CC904214 | F72: C245 | G72: 44613 | H72: 4474800 | I72: E122 | J72: E125 | K72: =VLOOKUP(E72,'Test 3'!$E$4:$S$604,15,0) -> Pass
C75: Summary of transactions value spread (Test 5)
C77: Row Labels | D77: Sum of Recorded Revenue | E77: Count of Recorded Revenue2
C78: FY 20-21
C79: 40L to 50L | D79: 18678070 | E79: 4
C80: 50L and above | D80: 53671740 | E80: 7
C81: Below 30L | D81: 86586570 | E81: 248
C82: FY 21-22
C83: 40L to 50L | D83: 172634600 | E83: 38
C84: 50L and above | D84: 55351920 | E84: 6
C85: Below 30L | D85: 93920520 | E85: 297
C86: Grand Total | D86: 480843420 | E86: 600
B89: Revenue Data - Categorized
B91: S. No. | C91: Transaction Id | D91: Posting cum auto-invoice Generation Date | E91: Recorded Revenue | F91: Value Category | G91: Date Category
B92: 1 | C92: 2021O81900 | D92: 43922 | E92: 483830 | F92: =IF(E92<3000000,"Below 30L",IF(E92<4000000,"30L to 40L",IF(E92<5000000,"40L to 50L",IF(E92>=5000000,"50L and above")))) -> Below 30L | G92: =IF(AND(DATE(2021,4,1)<=D92,D92<=DATE(2022,3,31)),"FY 21-22","FY 20-21") -> FY 20-21
B93: 2 | C93: 2021M11625 | D93: 43924 | E93: 462100 | F93: =IF(E93<3000000,"Below 30L",IF(E93<4000000,"30L to 40L",IF(E93<5000000,"40L to 50L",IF(E93>=5000000,"50L and above")))) -> Below 30L | G93: =IF(AND(DATE(2021,4,1)<=D93,D93<=DATE(2022,3,31)),"FY 21-22","FY 20-21") -> FY 20-21
B94: 3 | C94: 2021S01216 | D94: 43924 | E94: 372600 | F94: =IF(E94<3000000,"Below 30L",IF(E94<4000000,"30L to 40L",IF(E94<5000000,"40L to 50L",IF(E94>=5000000,"50L and above")))) -> Below 30L | G94: =IF(AND(DATE(2021,4,1)<=D94,D94<=DATE(2022,3,31)),"FY 21-22","FY 20-21") -> FY 20-21
B95: 4 | C95: 2021V81178 | D95: 43925 | E95: 34370 | F95: =IF(E95<3000000,"Below 30L",IF(E95<4000000,"30L to 40L",IF(E95<5000000,"40L to 50L",IF(E95>=5000000,"50L and above")))) -> Below 30L | G95: =IF(AND(DATE(2021,4,1)<=D95,D95<=DATE(2022,3,31)),"FY 21-22","FY 20-21") -> FY 20-21
B96: 5 | C96: 2021C71611 | D96: 43925 | E96: 24190 | F96: =IF(E96<3000000,"Below 30L",IF(E96<4000000,"30L to 40L",IF(E96<5000000,"40L to 50L",IF(E96>=5000000,"50L and above")))) -> Below 30L | G96: =IF(AND(DATE(2021,4,1)<=D96,D96<=DATE(2022,3,31)),"FY 21-22","FY 20-21") -> FY 20-21
...

Sheet Test 6
A2: 6 | B2: List of Related Parties identified
C4: ID | D4: Party Name
C5: C236 | D5: Mint IT Pvt Ltd
C6: C237 | D6: Forest Green IT Ltd
C7: C238 | D7: Chartreuse Software Pvt Ltd
C8: C239 | D8: Amber IT Pvt Ltd
C9: C240 | D9: Mustard IT Ltd
B11: Customer Spread analysis (Test 6)
E12: Total Revenue (Two years) | F12: No. of parties | G12: Avg revenue per party (in Lakhs)
D13: RP | E13: =SUMIF($H$31:$H$79,"YES",$E$31:$E$79) -> 134294030 | F13: =COUNTIF($H$31:$H$79,"YES") -> 5 | G13: =(E13/F13)/10^5 -> 268.58806
D14: Non RP | E14: =SUMIF($H$31:$H$79,"NO",$E$31:$E$79) -> 346549390 | F14: =COUNTIF($H$31:$H$79,"NO") -> 44 | G14: =(E14/F14)/10^5 -> 78.761225
E15: =SUM(E13:E14) -> 480843420 | F15: =SUM(F13:F14) -> 49
C17: FY wise breakup
D18: Sum of Recorded Revenue | E18: Column Labels
D19: Row Labels | E19: RP | F19: NON-RP | G19: Grand Total
D20: FY 20-21 | E20: 9728230 | F20: 149208150 | G20: 158936380
D21: FY 21-22 | E21: 124565800 | F21: 197341240 | G21: 321907040
D22: Grand Total | E22: 134294030 | F22: 346549390 | G22: 480843420
C24: % of Total (from above)
D25: FY | E25: RP | F25: NON-RP | G25: Grand Total
D26: FY 20-21 | E26: =E20/G20 -> 0.061208328 | F26: =F20/G20 -> 0.93879167 | G26: =SUM(E26:F26) -> 1
D27: FY 21-22 | E27: =E21/G21 -> 0.38696202 | F27: =F21/G21 -> 0.61303798 | G27: =SUM(E27:F27) -> 1
D30: Row Labels | E30: Sum of Recorded Revenue | G30: Name of customer | H30: Related party? | I30: Value of Transaction
D31: C200 | E31: 2810360 | G31: =VLOOKUP(D31,'Data - Customer Master'!$C$3:$D$51,2,0) -> Red Software Pvt Ltd | H31: =IFERROR(IF(MATCH(G31,$D$5:$D$9,0)>0,"YES"),"NO") -> NO | I31: =E31 -> 2810360
D32: C201 | E32: 3127110 | G32: =VLOOKUP(D32,'Data - Customer Master'!$C$3:$D$51,2,0) -> Yellow Software Pvt Ltd | H32: =IFERROR(IF(MATCH(G32,$D$5:$D$9,0)>0,"YES"),"NO") -> NO | I32: =E32 -> 3127110
D33: C202 | E33: 16470920 | G33: =VLOOKUP(D33,'Data - Customer Master'!$C$3:$D$51,2,0) -> Blue Tech Solutions Pvt Ltd | H33: =IFERROR(IF(MATCH(G33,$D$5:$D$9,0)>0,"YES"),"NO") -> NO | I33: =E33 -> 16470920
D34: C203 | E34: 4323180 | G34: =VLOOKUP(D34,'Data - Customer Master'!$C$3:$D$51,2,0) -> Green Solutions Pvt Ltd | H34: =IFERROR(IF(MATCH(G34,$D$5:$D$9,0)>0,"YES"),"NO") -> NO | I34: =E34 -> 4323180
D35: C204 | E35: 4389430 | G35: =VLOOKUP(D35,'Data - Customer Master'!$C$3:$D$51,2,0) -> Orange Digital Pvt Ltd | H35: =IFERROR(IF(MATCH(G35,$D$5:$D$9,0)>0,"YES"),"NO") -> NO | I35: =E35 -> 4389430
D36: C205 | E36: 4532640 | G36: =VLOOKUP(D36,'Data - Customer Master'!$C$3:$D$51,2,0) -> Purple IT Pvt Ltd | H36: =IFERROR(IF(MATCH(G36,$D$5:$D$9,0)>0,"YES"),"NO") -> NO | I36: =E36 -> 4532640
D37: C206 | E37: 2728190 | G37: =VLOOKUP(D37,'Data - Customer Master'!$C$3:$D$51,2,0) -> Black Infocom Pvt Ltd | H37: =IFERROR(IF(MATCH(G37,$D$5:$D$9,0)>0,"YES"),"NO") -> NO | I37: =E37 -> 2728190
D38: C207 | E38: 4858460 | G38: =VLOOKUP(D38,'Data - Customer Master'!$C$3:$D$51,2,0) -> White Software Ltd | H38: =IFERROR(IF(MATCH(G38,$D$5:$D$9,0)>0,"YES"),"NO") -> NO | I38: =E38 -> 4858460
D39: C208 | E39: 2600080 | G39: =VLOOKUP(D39,'Data - Customer Master'!$C$3:$D$51,2,0) -> Gray Digital Pvt Ltd | H39: =IFERROR(IF(MATCH(G39,$D$5:$D$9,0)>0,"YES"),"NO") -> NO | I39: =E39 -> 2600080
D40: C209 | E40: 5255940 | G40: =VLOOKUP(D40,'Data - Customer Master'!$C$3:$D$51,2,0) -> Brown Computers Ltd | H40: =IFERROR(IF(MATCH(G40,$D$5:$D$9,0)>0,"YES"),"NO") -> NO | I40: =E40 -> 5255940
D41: C210 | E41: 7831740 | G41: =VLOOKUP(D41,'Data - Customer Master'!$C$3:$D$51,2,0) -> Beige IT Ltd | H41: =IFERROR(IF(MATCH(G41,$D$5:$D$9,0)>0,"YES"),"NO") -> NO | I41: =E41 -> 7831740
D42: C211 | E42: 1790880 | G42: =VLOOKUP(D42,'Data - Customer Master'!$C$3:$D$51,2,0) -> Cream Software Ltd | H42: =IFERROR(IF(MATCH(G42,$D$5:$D$9,0)>0,"YES"),"NO") -> NO | I42: =E42 -> 1790880
... D79: C248 | E79: 7139210 | G79: =VLOOKUP(D79,'Data - Customer Master'!$C$3:$D$51,2,0) -> Mocha Infocom Ltd | H79: =IFERROR(IF(MATCH(G79,$D$5:$D$9,0)>0,"YES"),"NO") -> NO | I79: =E79 -> 7139210
D80: Grand Total | E80: 480843420 | I80: =SUM(I31:I79) -> 480843420

Sheet Test 7
A2: 7 | B2: Contract Tracker Analysis
B3: System generated Unique Contract No. | C3: Requisite Party | D3: % Work Done | E3: Type of Work | F3: Completed/Contract-In-Progress | G3: Controller/Supervisor | I3: Completed month - Revenue sheet | J3: Match testing
B4: CC101931 | C4: C221 | D4: 1 | E4: Consulting | F4: =IF(D4=100%,"Completed","Contract-In-Progress") -> Completed | G4: SM | I4: =IFERROR(VLOOKUP(B4,'Test 1,2'!$E$4:$I$604,5,0),"NOT BILLED") -> Jul | J4: =IF(I4<>"NOT BILLED",IF(D4=100%,"PASS","FLAG"),IF(D4<100%,"PASS","FLAG")) -> PASS
B5: CC102530 | C5: C218 | D5: 1 | E5: Consulting | F5: =IF(D5=100%,"Completed","Contract-In-Progress") -> Completed | G5: SM | I5: =IFERROR(VLOOKUP(B5,'Test 1,2'!$E$4:$I$604,5,0),"NOT BILLED") -> Apr | J5: =IF(I5<>"NOT BILLED",IF(D5=100%,"PASS","FLAG"),IF(D5<100%,"PASS","FLAG")) -> PASS
B6: CC102948 | C6: C242 | D6: 1 | E6: Service | F6: =IF(D6=100%,"Completed","Contract-In-Progress") -> Completed | G6: SM | I6: =IFERROR(VLOOKUP(B6,'Test 1,2'!$E$4:$I$604,5,0),"NOT BILLED") -> Jul | J6: =IF(I6<>"NOT BILLED",IF(D6=100%,"PASS","FLAG"),IF(D6<100%,"PASS","FLAG")) -> PASS
B7: CC105500 | C7: C226 | D7: 1 | E7: Service | F7: =IF(D7=100%,"Completed","Contract-In-Progress") -> Completed | G7: SM | I7: =IFERROR(VLOOKUP(B7,'Test 1,2'!$E$4:$I$604,5,0),"NOT BILLED") -> Sep | J7: =IF(I7<>"NOT BILLED",IF(D7=100%,"PASS","FLAG"),IF(D7<100%,"PASS","FLAG")) -> PASS
B8: CC106478 | C8: C211 | D8: 1 | E8: Service | F8: =IF(D8=100%,"Completed","Contract-In-Progress") -> Completed | G8: SM | I8: =IFERROR(VLOOKUP(B8,'Test 1,2'!$E$4:$I$604,5,0),"NOT BILLED") -> Jul | J8: =IF(I8<>"NOT BILLED",IF(D8=100%,"PASS","FLAG"),IF(D8<100%,"PASS","FLAG")) -> PASS
B9: CC108593 | C9: C246 | D9: 1 | E9: Consulting | F9: =IF(D9=100%,"Completed","Contract-In-Progress") -> Completed | G9: SM | I9: =IFERROR(VLOOKUP(B9,'Test 1,2'!$E$4:$I$604,5,0),"NOT BILLED") -> Jan | J9: =IF(I9<>"NOT BILLED",IF(D9=100%,"PASS","FLAG"),IF(D9<100%,"PASS","FLAG")) -> PASS
B10: CC108757 | C10: C241 | D10: 1 | E10: Consulting | F10: =IF(D10=100%,"Completed","Contract-In-Progress") -> Completed | G10: CM | I10: =IFERROR(VLOOKUP(B10,'Test 1,2'!$E$4:$I$604,5,0),"NOT BILLED") -> Jan | J10: =IF(I10<>"NOT BILLED",IF(D10=100%,"PASS","FLAG"),IF(D10<100%,"PASS","FLAG")) -> PASS
B11: CC113941 | C11: C229 | D11: 1 | E11: Service | F11: =IF(D11=100%,"Completed","Contract-In-Progress") -> Completed | G11: CM | I11: =IFERROR(VLOOKUP(B11,'Test 1,2'!$E$4:$I$604,5,0),"NOT BILLED") -> Jul | J11: =IF(I11<>"NOT BILLED",IF(D11=100%,"PASS","FLAG"),IF(D11<100%,"PASS","FLAG")) -> PASS
B12: CC114003 | C12: C218 | D12: 1 | E12: Service | F12: =IF(D12=100%,"Completed","Contract-In-Progress") -> Completed | G12: SM | I12: =IFERROR(VLOOKUP(B12,'Test 1,2'!$E$4:$I$604,5,0),"NOT BILLED") -> Nov | J12: =IF(I12<>"NOT BILLED",IF(D12=100%,"PASS","FLAG"),IF(D12<100%,"PASS","FLAG")) -> PASS
B13: CC114057 | C13: C230 | D13: 1 | E13: Consulting | F13: =IF(D13=100%,"Completed","Contract-In-Progress") -> Completed | G13: SM | I13: =IFERROR(VLOOKUP(B13,'Test 1,2'!$E$4:$I$604,5,0),"NOT BILLED") -> Nov | J13: =IF(I13<>"NOT BILLED",IF(D13=100%,"PASS","FLAG"),IF(D13<100%,"PASS","FLAG")) -> PASS
B14: CC116382 | C14: C204 | D14: 1 | E14: Consulting | F14: =IF(D14=100%,"Completed","Contract-In-Progress") -> Completed | G14: SM | I14: =IFERROR(VLOOKUP(B14,'Test 1,2'!$E$4:$I$604,5,0),"NOT BILLED") -> Mar | J14: =IF(I14<>"NOT BILLED",IF(D14=100%,"PASS","FLAG"),IF(D14<100%,"PASS","FLAG")) -> PASS
B15: CC117699 | C15: C240 | D15: 1 | E15: Service | F15: =IF(D15=100%,"Completed","Contract-In-Progress") -> Completed | G15: CM | I15: =IFERROR(VLOOKUP(B15,'Test 1,2'!$E$4:$I$604,5,0),"NOT BILLED") -> May | J15: =IF(I15<>"NOT BILLED",IF(D15=100%,"PASS","FLAG"),IF(D15<100%,"PASS","FLAG")) -> PASS
... B626: CC487134 | C626: CC233 | D626: 0.45 | E626: Service | F626: =IF(D626=100%,"Completed","Contract-In-Progress") -> Contract-In-Progress | G626: SM | I626: =IFERROR(VLOOKUP(B626,'Test 1,2'!$E$4:$I$604,5,0),"NOT BILLED") -> NOT BILLED | J626: =IF(I626<>"NOT BILLED",IF(D626=100%,"PASS","FLAG"),IF(D626<100%,"PASS","FLAG")) -> PASS

Sheet Test 8
A2: 8 | B2: Pending receivables Analysis | G2: Current Date | H2: 44666
B4: System generated Unique Contract No. | C4: Completed/In-Progress | D4: Controller/Supervisor | E4: Invoice Date | F4: Date of receipt in bank | G4: Value of transaction | H4: No of days outstanding | I4: Category outstanding | J4: Whether Flagged in transaction time-screening? | K4: Customer ID | L4: Whether related party? | M4: Creator | N4: Approver
B5: CC714760 | C5: Completed | D5: SM | E5: 44325 | F5: Pending | G5: =VLOOKUP(B5,'Test 1,2'!$E$4:$J$604,6,0) -> 4279450 | H5: =$H$2-E5 -> 341 | I5: =IF(H5<50,"Below 50 days",IF(H5<100,"Below 100 days","100 days and above")) -> 100 days and above | J5: =VLOOKUP(B5,'Test 3'!$E$4:$U$604,15,0) -> Red Flag | K5: =VLOOKUP(B5,'Test 1,2'!$E$4:$F$604,2,0) -> C239 | L5: =IFERROR(VLOOKUP(K5,'Test 6'!$C$4:$D$9,2,0),"NOT RP") -> Amber IT Pvt Ltd | M5: =VLOOKUP(B5,'Test 1,2'!$E$4:$N$604,9,0) -> E123 | N5: =VLOOKUP(B5,'Test 1,2'!$E$4:$N$604,10,0) -> E125
B6: CC464231 | C6: Completed | D6: CM | E6: 44332 | F6: Pending | G6: =VLOOKUP(B6,'Test 1,2'!$E$4:$J$604,6,0) -> 4951880 | H6: =$H$2-E6 -> 334 | I6: =IF(H6<50,"Below 50 days",IF(H6<100,"Below 100 days","100 days and above")) -> 100 days and above | J6: =VLOOKUP(B6,'Test 3'!$E$4:$U$604,15,0) -> Red Flag | K6: =VLOOKUP(B6,'Test 1,2'!$E$4:$F$604,2,0) -> C239 | L6: =IFERROR(VLOOKUP(K6,'Test 6'!$C$4:$D$9,2,0),"NOT RP") -> Amber IT Pvt Ltd | M6: =VLOOKUP(B6,'Test 1,2'!$E$4:$N$604,9,0) -> E125 | N6: =VLOOKUP(B6,'Test 1,2'!$E$4:$N$604,10,0) -> E126
B7: CC117699 | C7: Completed | D7: CM | E7: 44338 | F7: Pending | G7: =VLOOKUP(B7,'Test 1,2'!$E$4:$J$604,6,0) -> 4672170 | H7: =$H$2-E7 -> 328 | I7: =IF(H7<50,"Below 50 days",IF(H7<100,"Below 100 days","100 days and above")) -> 100 days and above | J7: =VLOOKUP(B7,'Test 3'!$E$4:$U$604,15,0) -> Red Flag | K7: =VLOOKUP(B7,'Test 1,2'!$E$4:$F$604,2,0) -> C240 | L7: =IFERROR(VLOOKUP(K7,'Test 6'!$C$4:$D$9,2,0),"NOT RP") -> Mustard IT Ltd | M7: =VLOOKUP(B7,'Test 1,2'!$E$4:$N$604,9,0) -> E125 | N7: =VLOOKUP(B7,'Test 1,2'!$E$4:$N$604,10,0) -> E126
B8: CC551324 | C8: Completed | D8: SM | E8: 44339 | F8: Pending | G8: =VLOOKUP(B8,'Test 1,2'!$E$4:$J$604,6,0) -> 4062620 | H8: =$H$2-E8 -> 327 | I8: =IF(H8<50,"Below 50 days",IF(H8<100,"Below 100 days","100 days and above")) -> 100 days and above | J8: =VLOOKUP(B8,'Test 3'!$E$4:$U$604,15,0) -> Red Flag | K8: =VLOOKUP(B8,'Test 1,2'!$E$4:$F$604,2,0) -> C240 | L8: =IFERROR(VLOOKUP(K8,'Test 6'!$C$4:$D$9,2,0),"NOT RP") -> Mustard IT Ltd | M8: =VLOOKUP(B8,'Test 1,2'!$E$4:$N$604,9,0) -> E123 | N8: =VLOOKUP(B8,'Test 1,2'!$E$4:$N$604,10,0) -> E125
B9: CC609741 | C9: Completed | D9: CM | E9: 44345 | F9: Pending | G9: =VLOOKUP(B9,'Test 1,2'!$E$4:$J$604,6,0) -> 4611710 | H9: =$H$2-E9 -> 321 | I9: =IF(H9<50,"Below 50 days",IF(H9<100,"Below 100 days","100 days and above")) -> 100 days and above | J9: =VLOOKUP(B9,'Test 3'!$E$4:$U$604,15,0) -> Red Flag | K9: =VLOOKUP(B9,'Test 1,2'!$E$4:$F$604,2,0) -> C236 | L9: =IFERROR(VLOOKUP(K9,'Test 6'!$C$4:$D$9,2,0),"NOT RP") -> Mint IT Pvt Ltd | M9: =VLOOKUP(B9,'Test 1,2'!$E$4:$N$604,9,0) -> E125 | N9: =VLOOKUP(B9,'Test 1,2'!$E$4:$N$604,10,0) -> E126
B10: CC889005 | C10: Completed | D10: SM | E10: 44353 | F10: Pending | G10: =VLOOKUP(B10,'Test 1,2'!$E$4:$J$604,6,0) -> 4080130 | H10: =$H$2-E10 -> 313 | I10: =IF(H10<50,"Below 50 days",IF(H10<100,"Below 100 days","100 days and above")) -> 100 days and above | J10: =VLOOKUP(B10,'Test 3'!$E$4:$U$604,15,0) -> Red Flag | K10: =VLOOKUP(B10,'Test 1,2'!$E$4:$F$604,2,0) -> C236 | L10: =IFERROR(VLOOKUP(K10,'Test 6'!$C$4:$D$9,2,0),"NOT RP") -> Mint IT Pvt Ltd | M10: =VLOOKUP(B10,'Test 1,2'!$E$4:$N$604,9,0) -> E124 | N10: =VLOOKUP(B10,'Test 1,2'!$E$4:$N$604,10,0) -> E125
B11: CC758767 | C11: Completed | D11: SM | E11: 44373 | F11: Pending | G11: =VLOOKUP(B11,'Test 1,2'!$E$4:$J$604,6,0) -> 4330520 | H11: =$H$2-E11 -> 293 | I11: =IF(H11<50,"Below 50 days",IF(H11<100,"Below 100 days","100 days and above")) -> 100 days and above | J11: =VLOOKUP(B11,'Test 3'!$E$4:$U$604,15,0) -> Red Flag | K11: =VLOOKUP(B11,'Test 1,2'!$E$4:$F$604,2,0) -> C240 | L11: =IFERROR(VLOOKUP(K11,'Test 6'!$C$4:$D$9,2,0),"NOT RP") -> Mustard IT Ltd | M11: =VLOOKUP(B11,'Test 1,2'!$E$4:$N$604,9,0) -> E123 | N11: =VLOOKUP(B11,'Test 1,2'!$E$4:$N$604,10,0) -> E125
B12: CC958168 | C12: Completed | D12: CM | E12: 44381 | F12: Pending | G12: =VLOOKUP(B12,'Test 1,2'!$E$4:$J$604,6,0) -> 4673740 | H12: =$H$2-E12 -> 285 | I12: =IF(H12<50,"Below 50 days",IF(H12<100,"Below 100 days","100 days and above")) -> 100 days and above | J12: =VLOOKUP(B12,'Test 3'!$E$4:$U$604,15,0) -> Red Flag | K12: =VLOOKUP(B12,'Test 1,2'!$E$4:$F$604,2,0) -> C236 | L12: =IFERROR(VLOOKUP(K12,'Test 6'!$C$4:$D$9,2,0),"NOT RP") -> Mint IT Pvt Ltd | M12: =VLOOKUP(B12,'Test 1,2'!$E$4:$N$604,9,0) -> E125 | N12: =VLOOKUP(B12,'Test 1,2'!$E$4:$N$604,10,0) -> E126
B13: CC504719 | C13: Completed | D13: SM | E13: 44388 | F13: Pending | G13: =VLOOKUP(B13,'Test 1,2'!$E$4:$J$604,6,0) -> 4059510 | H13: =$H$2-E13 -> 278 | I13: =IF(H13<50,"Below 50 days",IF(H13<100,"Below 100 days","100 days and above")) -> 100 days and above | J13: =VLOOKUP(B13,'Test 3'!$E$4:$U$604,15,0) -> Red Flag | K13: =VLOOKUP(B13,'Test 1,2'!$E$4:$F$604,2,0) -> C240 | L13: =IFERROR(VLOOKUP(K13,'Test 6'!$C$4:$D$9,2,0),"NOT RP") -> Mustard IT Ltd | M13: =VLOOKUP(B13,'Test 1,2'!$E$4:$N$604,9,0) -> E123 | N13: =VLOOKUP(B13,'Test 1,2'!$E$4:$N$604,10,0) -> E125
B14: CC483508 | C14: Completed | D14: SM | E14: 44395 | F14: Pending | G14: =VLOOKUP(B14,'Test 1,2'!$E$4:$J$604,6,0) -> 4211080 | H14: =$H$2-E14 -> 271 | I14: =IF(H14<50,"Below 50 days",IF(H14<100,"Below 100 days","100 days and above")) -> 100 days and above | J14: =VLOOKUP(B14,'Test 3'!$E$4:$U$604,15,0) -> Red Flag | K14: =VLOOKUP(B14,'Test 1,2'!$E$4:$F$604,2,0) -> C240 | L14: =IFERROR(VLOOKUP(K14,'Test 6'!$C$4:$D$9,2,0),"NOT RP") -> Mustard IT Ltd | M14: =VLOOKUP(B14,'Test 1,2'!$E$4:$N$604,9,0) -> E124 | N14: =VLOOKUP(B14,'Test 1,2'!$E$4:$N$604,10,0) -> E125
B15: CC158828 | C15: Completed | D15: SM | E15: 44415 | F15: Pending | G15: =VLOOKUP(B15,'Test 1,2'!$E$4:$J$604,6,0) -> 4250210 | H15: =$H$2-E15 -> 251 | I15: =IF(H15<50,"Below 50 days",IF(H15<100,"Below 100 days","100 days and above")) -> 100 days and above | J15: =VLOOKUP(B15,'Test 3'!$E$4:$U$604,15,0) -> Red Flag | K15: =VLOOKUP(B15,'Test 1,2'!$E$4:$F$604,2,0) -> C240 | L15: =IFERROR(VLOOKUP(K15,'Test 6'!$C$4:$D$9,2,0),"NOT RP") -> Mustard IT Ltd | M15: =VLOOKUP(B15,'Test 1,2'!$E$4:$N$604,9,0) -> E123 | N15: =VLOOKUP(B15,'Test 1,2'!$E$4:$N$604,10,0) -> E125
B16: CC859081 | C16: Completed | D16: CM | E16: 44423 | F16: Pending | G16: =VLOOKUP(B16,'Test 1,2'!$E$4:$J$604,6,0) -> 4927020 | H16: =$H$2-E16 -> 243 | I16: =IF(H16<50,"Below 50 days",IF(H16<100,"Below 100 days","100 days and above")) -> 100 days and above | J16: =VLOOKUP(B16,'Test 3'!$E$4:$U$604,15,0) -> Red Flag | K16: =VLOOKUP(B16,'Test 1,2'!$E$4:$F$604,2,0) -> C239 | L16: =IFERROR(VLOOKUP(K16,'Test 6'!$C$4:$D$9,2,0),"NOT RP") -> Amber IT Pvt Ltd | M16: =VLOOKUP(B16,'Test 1,2'!$E$4:$N$604,9,0) -> E125 | N16: =VLOOKUP(B16,'Test 1,2'!$E$4:$N$604,10,0) -> E126
... B47: CC498363 | C47: Completed | D47: SM | E47: 44634 | F47: Pending | G47: =VLOOKUP(B47,'Test 1,2'!$E$4:$J$604,6,0) -> 371640 | H47: =$H$2-E47 -> 32 | I47: =IF(H47<50,"Below 50 days",IF(H47<100,"Below 100 days","100 days and above")) -> Below 50 days | J47: =VLOOKUP(B47,'Test 3'!$E$4:$U$604,15,0) -> Pass | K47: =VLOOKUP(B47,'Test 1,2'!$E$4:$F$604,2,0) -> C213 | L47: =IFERROR(VLOOKUP(K47,'Test 6'!$C$4:$D$9,2,0),"NOT RP") -> NOT RP | M47: =VLOOKUP(B47,'Test 1,2'!$E$4:$N$604,9,0) -> E116 | N47: =VLOOKUP(B47,'Test 1,2'!$E$4:$N$604,10,0) -> E120
G48: =SUM(G5:G47) -> 132736650
B50: Chart for outstanding reveivables - Customer wise + Value of revenue + Days outanding
B69: Summary of receivable analysis - RP & Non-RP (Test 8)
B70: Sum of Value of transaction | C70: Column Labels
C71: 100 days and above | D71: Below 100 days | F71: Below 50 days
B72: Row Labels | C72: Red Flag | D72: Pass | E72: Red Flag | F72: Pass
B73: Amber IT Pvt Ltd | C73: 18433680 | E73: 4651520
B74: Chartreuse Software Pvt Ltd | C74: 22831820
B75: Forest Green IT Ltd | C75: 17973140
B76: Mint IT Pvt Ltd | C76: 18183280 | D76: 49630 | E76: 4847720
B77: Mustard IT Ltd | C77: 34872920
B78: NOT RP | D78: 9010790 | F78: 1882150
B79: Grand Total | C79: 112294840 | D79: 9060420 | E79: 9499240 | F79: 1882150
F81: =SUM(C79:F79) -> 132736650

Sheet Test 9
B2: Employee/Board | C2: Level | D2: Employee ID | E2: No of Shares | F2: Current Book value in Rupees | G2: Vested/Not-vested | H2: Board & Shareholder Approval | J2: Involved in transaction time-screening flag?
B3: Employee | C3: SM | D3: E123 | E3: 250000 | F3: 10 | G3: Vested | H3: Duly Received | J3: Yes
B4: Employee | C4: SM | D4: E124 | E4: 250000 | F4: 10 | G4: Vested | H4: Duly Received | J4: Yes
B5: Employee | C5: CM | D5: E125 | E5: 500000 | F5: 10 | G5: Vested | H5: Duly Received | J5: Yes
B6: Employee | C6: CFO | D6: E126 | E6: 700000 | F6: 10 | G6: Vested | H6: Duly Received | J6: Yes
B7: Employee | C7: Director 1 | D7: E127 | E7: 600000 | F7: 10 | G7: Vested | H7: Duly Received | J7: No
B8: Employee | C8: Director 2 | D8: E128 | E8: 600000 | F8: 10 | G8: Vested | H8: Duly Received | J8: No
B9: Employee | C9: Director 3 | D9: E129 | E9: 600000 | F9: 10 | G9: Vested | H9: Duly Received | J9: No
B10: Board | C10: Director 4 | D10: NA | E10: 600000 | F10: 10 | G10: Vested | H10: Duly Received | J10: NA
B11: Board | C11: Director 5 | D11: NA | E11: 600000 | F11: 10 | G11: Vested | H11: Duly Received | J11: NA
B12: Board | C12: MD | D12: NA | E12: 800000 | F12: 10 | G12: Vested | H12: Duly Received | J12: NA
B13: Board | C13: Chairman | D13: NA | E13: 1000000 | F13: 10 | G13: Vested | H13: Duly Received | J13: NA
E15: =SUM(E3:E13) -> 6500000
B17: Mapping Employee codes from Red Flag entries from Transaction time-screening (Test 9)
B19: Transaction time-screeing results | C19: Red Flag
B21: Row Labels | C21: Sum of Recorded Revenue
B22: E125
B23: E123 | C23: 38526040 | H23: Employee ID | I23: Level | J23: ESOP Shares
B24: E124 | C24: 21071430 | H24: E123 | I24: SM | J24: 250000
